Workbook

Sheet Instrucciones
A1: Registro operativo de desayuno (BM)
A3: CÓMO USAR
A4: 1. Vaya a la hoja Registro.
A5: 2. En cada línea ponga la Fecha (AAAA-MM-DD). Misma fecha = UN solo desayuno en BM.
A6: 3. Huéspedes (por línea, se SUMAN en el día):
A7: • 1 = nuevo comensal (cuenta 1 persona).
A8: • 0 = mismo comensal que pide otro plato (NO suma persona).
A9: • Vacío = igual que 0 (no suma).
A10: Ejemplo: comensal pide inglés + café → fila inglés Huespedes=1, fila café=0.
A11: Total del día = suma de la columna (solo los 1).
A12: 4. Tipo: Receta (plato/bebida), Extra (buffet rápido) o Producto.
A13: 5. Nombre: elija del desplegable (lista en hoja Catalogo).
... A53: Al regenerar la plantilla NO se borran filas ya rellenadas en hojas de registro.

Sheet Registro
A1: Fecha | B1: Huespedes | C1: Tipo | D1: Nombre | E1: Cantidad ↑↓ | F1: Extra1 | G1: Cant1 ↑↓ | H1: Extra2 | I1: Cant2 ↑↓ | J1: Extra3 | K1: Cant3 ↑↓ | L1: Extra4 | M1: Cant4 ↑↓ | N1: Omitir1 | O1: Omitir2 | P1: Notas | Q1: Importado
A2: 46254 | B2: 1 | C2: Receta | D2: Huevo frito | E2: 3 | Q2: OK d181
A3: 46254 | B3: 1 | C3: Receta | D3: Sandwich vegetal | E3: 1 | Q3: OK d181
A4: 46254 | B4: 1 | C4: Receta | D4: Huevos revueltos | E4: 1 | F4: Espinacas | G4: 1 | Q4: OK d181
A5: 46254 | B5: 1 | C5: Receta | D5: Sandwich de la casa | E5: 1 | Q5: OK d181
A6: 46254 | B6: 1 | C6: Receta | D6: Huevo pochado | E6: 1 | F6: Tostada | G6: 1 | Q6: OK d181
A7: 46254 | B7: 1 | C7: Receta | D7: Desayuno ingles | E7: 1 | N7: Champi | O7: Hashbrown | Q7: OK d181
A8: 46254 | B8: 1 | C8: Receta | D8: Desayuno ingles | E8: 1 | Q8: OK d181
A9: 46254 | B9: 1 | C9: Receta | D9: Tortilla | E9: 1 | F9: Queso gouda | G9: 1 | H9: Champi | I9: 1 | Q9: OK d181
A10: 46254 | B10: 1 | C10: Receta | D10: Desayuno ingles | E10: 1 | F10: Huevos revueltos | G10: 1 | N10: Huevo frito | Q10: OK d181
A11: 46254 | B11: 1 | C11: Receta | D11: Huevo pochado | E11: 2 | Q11: OK d181
A12: 46254 | B12: 1 | C12: Receta | D12: Huevos revueltos | E12: 1 | Q12: OK d181
A13: 46254 | B13: 1 | C13: Receta | D13: Huevo frito | E13: 1 | Q13: OK d181
A14: 46254 | B14: 1 | C14: Receta | D14: Tostada del dia | E14: 1 | Q14: OK d181
A15: 46254 | B15: 1 | C15: Receta | D15: Huevo frito | E15: 1 | Q15: OK d181
A16: 46254 | B16: 1 | C16: Receta | D16: Tostada del dia | E16: 1 | Q16: OK d181
A17: 46254 | B17: 0 | C17: Receta | D17: Tortilla | E17: 1 | F17: Champi | G17: 1 | H17: Jamon cocido | I17: 1 | J17: Queso cheddar | K17: 1 | Q17: OK d181
A18: 46254 | B18: 1 | C18: Receta | D18: Huevo frito | E18: 2 | F18: Hashbrown | G18: 1 | Q18: OK d181
A19: 46254 | B19: 1 | C19: Receta | D19: Tortilla | E19: 1 | F19: Tomate | G19: 1 | H19: Hashbrown | I19: 1 | Q19: OK d181
A20: 46254 | B20: 1 | C20: Receta | D20: Sandwich mixto | E20: 1 | F20: Tostada integral | G20: 2 | N20: Sin tostada | Q20: OK d181
A21: 46254 | B21: 1 | C21: Producto | D21: Pan sin gluten | E21: 2 | F21: Huevo pochado | G21: 1 | Q21: OK d181
A22: 46254 | B22: 1 | C22: Receta | D22: Tortilla | E22: 1 | F22: Queso cheddar | G22: 1 | H22: Jamon cocido | I22: 1 | J22: Pimiento | K22: 1 | L22: Champi | M22: 1 | Q22: OK d181
A23: 46254 | B23: 1 | C23: Receta | D23: Tortilla | E23: 1 | F23: Queso cheddar | G23: 1 | H23: Jamon cocido | I23: 1 | J23: Pimiento | K23: 1 | L23: Champi | M23: 1 | Q23: OK d181
A24: 46254 | B24: 1 | C24: Receta | D24: Huevo pochado | E24: 1 | F24: Bacon | G24: 1 | H24: Champi | I24: 1 | Q24: OK d181
A25: 46254 | B25: 1 | C25: Receta | D25: Huevo pochado | E25: 2 | F25: Bacon | G25: 2 | Q25: OK d181
A26: 46254 | B26: 1 | C26: Receta | D26: Tortilla | E26: 1 | F26: Queso cheddar | G26: 1 | H26: Bacon | I26: 2 | J26: Alubias | K26: 1 | L26: Salchicha | M26: 2 | Q26: OK d181
A27: 46254 | B27: 1 | C27: Receta | D27: Tostada francesa | E27: 1 | F27: Hashbrown | G27: 1 | Q27: OK d181
A28: 46254 | B28: 1 | C28: Receta | D28: Huevo pochado | E28: 2 | F28: Bacon | G28: 2 | Q28: OK d181
A29: 46254 | B29: 1 | C29: Receta | D29: Huevo pochado | E29: 2 | Q29: OK d181
A30: 46254 | B30: 1 | C30: Receta | D30: Tortilla | E30: 1 | F30: Queso cheddar | G30: 1 | H30: Espinacas | I30: 1 | Q30: OK d181
A31: 46254 | B31: 1 | C31: Receta | D31: Tortilla | E31: 1 | F31: Queso cheddar | G31: 1 | H31: Espinacas | I31: 1 | Q31: OK d181

Sheet Catalogo
A1: Recetas_desayuno | B1: Extras_rapidos | C1: Nombres_todos | D1: Huevos_ofrecidos | E1: Extra_u_Omitir | F1: Panes_ofrecidos | G1: Recetas_comida | H1: Recetas_cena | I1: Bebidas_desayuno
A2: Americano | B2: Queso cheddar | C2: Americano | D2: Huevo frito | E2: Queso cheddar | F2: Tostada | G2: Absolut | H2: Absolut | I2: Americano
A3: Botella Roger de Flor | B3: Queso gouda | C3: Botella Roger de Flor | D3: Huevo pochado | E3: Queso gouda | F3: Tostada integral | G3: Amaretto | H3: Amaretto | I3: Botella Roger de Flor
A4: Cafe con leche | B4: Bacon | C4: Cafe con leche | D4: Huevo cocido | E4: Bacon | F4: Tostada sin gluten | G4: Americano | H4: Americano | I4: Cafe con leche
A5: Cafe con leche descafeinado | B5: Jamon cocido | C5: Cafe con leche descafeinado | D5: Huevos revueltos | E5: Jamon cocido | F5: Pan blanco | G5: Aperol | H5: Aperol | I5: Cafe con leche descafeinado
A6: Cafe con leche semi | B6: Tostada | C6: Cafe con leche semi | D6: Sin huevo | E6: Tostada | F6: Pan integral | G6: Aperol Spritz | H6: Aperol Spritz | I6: Cafe con leche semi
A7: Capuchino | B7: Tostada integral | C7: Capuchino | E7: Tostada integral | F7: Pan sin gluten | G7: Bacalao en tempura | H7: Baileys | I7: Capuchino
A8: Capuchino semi | B8: Pan blanco | C8: Capuchino semi | E8: Pan blanco | F8: Sin tostada | G8: Baileys | H8: Beefeater | I8: Capuchino semi
A9: Cola Cao | B9: Pan integral | C9: Cola Cao | E9: Pan integral | G9: Banana split | H9: Blue Hawaii | I9: Cava Roger de Flor
A10: Cola Cao semi | B10: Tostada sin gluten | C10: Cola Cao semi | E10: Tostada sin gluten | G10: Beefeater | H10: Botella Anna Codorniu Mini | I10: Cola Cao
A11: Cortado | B11: Pan sin gluten | C11: Cortado | E11: Pan sin gluten | G11: Blue Hawaii | H11: Botella Codorniu Prima Vides | I11: Cola Cao semi
A12: Cortado semi | B12: Salchicha | C12: Cortado semi | E12: Salchicha | G12: Bola de helado | H12: Botella Ederra | I12: Cortado
A13: Desayuno ingles | B13: Hashbrown | C13: Desayuno ingles | E13: Hashbrown | G13: Botella Anna Codorniu Mini | H13: Botella El Grifo | I13: Cortado semi
A14: Espresso | B14: Champi | C14: Espresso | E14: Champi | G14: Botella Codorniu Prima Vides | H14: Botella Montecillo Blanco | I14: Espresso
A15: Espresso descafeinado | B15: Aguacate | C15: Espresso descafeinado | E15: Aguacate | G15: Botella Ederra | H15: Botella Montecillo Crianza | I15: Espresso descafeinado
A16: Estándar buffet desayuno diario | B16: Salmon | C16: Estándar buffet desayuno diario | E16: Salmon | G16: Botella El Grifo | H16: Botella Montecillo Reserva | I16: HELADO CHOCOLATE 5L
A17: Huevo cocido | B17: Tomate | C17: Huevo cocido | E17: Tomate | G17: Botella Montecillo Blanco | H17: Botella Montecillo Rosado | I17: HELADO VAINILLA 5L
A18: Huevo frito | B18: Cebolla | C18: Huevo frito | E18: Cebolla | G18: Botella Montecillo Crianza | H18: Botella Piper Heidsieck Brut | I18: Manzanilla
A19: Huevo pochado | B19: Alubias | C19: Huevo pochado | E19: Alubias | G19: Botella Montecillo Reserva | H19: Botella Piper Heidsieck Rose | I19: Seleccion de te
A20: Huevos revueltos | B20: Pimiento | C20: Huevos revueltos | E20: Pimiento | G20: Botella Montecillo Rosado | H20: Botella Roger de Flor | I20: SMOOTHIE B6 PITA-MANG-FRESA
... A25: Sandwich vegetal | B25: Huevo pochado | C25: Sandwich vegetal | E25: Huevo pochado | G25: Cafe Baileys | H25: Cafe irlandes | I25: Te verde
A26: Seleccion de te | B26: Huevo cocido | C26: Seleccion de te | E26: Huevo cocido | G26: Cafe con leche | H26: Caipirinha
A27: Te frutas del bosque | B27: Huevos revueltos | C27: Te frutas del bosque | E27: Huevos revueltos | G27: Cafe con leche descafeinado | H27: Campari
A28: Te negro | B28: Kiwi | C28: Te negro | E28: Kiwi | G28: Cafe con leche semi | H28: Caña NAO Marinera
A29: Te rojo | B29: Papaya | C29: Te rojo | E29: Papaya | G29: Cafe irlandes | H29: Capuchino
A30: Te verde | B30: Melon | C30: Te verde | E30: Melon | G30: Caipirinha | H30: Capuchino semi
A31: Tortilla | B31: Sandia | C31: Tortilla | E31: Sandia | G31: Calamares a la romana | H31: Carlos I
A32: Tostada champinones | B32: Pomelo | C32: Tostada champinones | E32: Pomelo | G32: Campari | H32: Cola Cao
A33: Tostada del dia | B33: Naranja | C33: Tostada del dia | E33: Naranja | G33: Caña NAO Marinera | H33: Cola Cao semi
A34: Tostada domingo | B34: Platano | C34: Tostada domingo | E34: Platano | G34: Capuchino | H34: Copa de sangria
A35: Tostada francesa | B35: Pina | C35: Tostada francesa | E35: Pina | G35: Capuchino semi | H35: Copa El Grifo
A36: Tostada jueves | B36: Melocoton almibar | C36: Tostada jueves | E36: Melocoton almibar | G36: Carlos I | H36: Copa Montecillo Blanco
A37: Tostada lunes | B37: Paleta iberica | C37: Tostada lunes | E37: Paleta iberica | G37: Cocktail de gambas | H37: Copa Montecillo Crianza
... A41: Tostada viernes | B41: Queso pimenton | C41: Tostada viernes | E41: Queso pimenton | G41: Copa El Grifo | H41: Cubitazo Estrella Galicia
B42: Queso fresco | C42: Queso cheddar | E42: Queso fresco | G42: Copa Montecillo Blanco | H42: Daiquiri
B43: Pan gallego | C43: Queso gouda | E43: Pan gallego | G43: Copa Montecillo Crianza | H43: Espresso
B44: Pan maiz | C44: Bacon | E44: Pan maiz | G44: Copa Montecillo Rosado | H44: Espresso descafeinado
B45: Pan centeno | C45: Jamon cocido | E45: Pan centeno | G45: Cortado | H45: Espresso Martini
B46: Baguettina | C46: Tostada | E46: Baguettina | G46: Cortado semi | H46: Gordon's
B47: Napolitana cacao | C47: Tostada integral | E47: Napolitana cacao | G47: Croquetas jamon serrano | H47: Grey Goose
...

Sheet Precios
A1: producto_id | B1: nombre | C1: coste_ud
A2: p1 | B2: Harina | C2: 1
A3: p2 | B3: Huevo | C3: 0.1
A4: b01 | B4: CROISSANT MINI CHOCOLATE CREMOSO 198UD 31G | C4: 0.3
A5: p03 | B5: ARTIS MINI CHAPATA 40GRS 160UD | C5: 0
A6: p04 | B6: PANECILLO S/GLUTEN BETINA 55GRS 45 UND | C6: 1.53
A7: p05 | B7: PAN GALLEGO BARRA 280GR 20 UND | C7: 1.34
A8: p06 | B8: PAN PIPAS CALABAZA 750GRS 12UDN | C8: 3.87
A9: p07 | B9: SMOOTHIE B6 PITA-MANG-FRESA | C9: 1.14
A10: p08 | B10: SURTIDO DE REPOSTERIA | C10: 0.64
A11: p09 | B11: MOLDE COMUN S/C 800GRS | C11: 2.89
A12: p10 | B12: HAMBURGUESA RUSTICA 60 GRS | C12: 2.85
A13: p11 | B13: MOLDE INTEGRAL S/C 1000 GRS | C13: 3.04
... A502: p416 | B502: GAMBON Nº1 | C502: 11.55

Sheet ConfigBuffet
A1: Seccion | B1: Orden | C1: Concepto | D1: ProductoId | E1: Unidad | F1: CantDefecto | G1: Tipo | H1: ProductoBote | I1: RecetaId | J1: Activo
A2: Bolleria | B2: 20 | C2: Napolitana cacao | D2: p251 | E2: ud | F2: 0.01 | G2: simple | J2: Si
A3: Bolleria | B3: 21 | C3: Chic crema | D3: p294 | E3: ud | F3: 0.003077 | G3: simple | J3: Si
A4: Bolleria | B4: 22 | C4: Lazo cereal | D4: p250 | E4: ud | F4: 0.005155 | G4: simple | J4: Si
A5: Bolleria | B5: 23 | C5: Croissant mantequilla | D5: p249 | E5: ud | F5: 0.003571 | G5: simple | J5: Si
A6: Bolleria | B6: 24 | C6: Croissant chocolate | D6: b01 | E6: ud | F6: 0.005051 | G6: simple | J6: Si
A7: Bolleria | B7: 25 | C7: Surtido reposteria | D7: p08 | E7: gr | F7: 0.05 | G7: simple | J7: Si
A8: Embutidos | B8: 10 | C8: Paleta iberica | D8: p358 | E8: gr | F8: 0.02 | G8: simple | J8: Si
A9: Embutidos | B9: 11 | C9: Mortadela | D9: p89 | E9: gr | F9: 0.02 | G9: simple | J9: Si
A10: Embutidos | B10: 12 | C10: Salchichon iberico | D10: p34 | E10: gr | F10: 0.02 | G10: simple | J10: Si
A11: Embutidos | B11: 13 | C11: Queso gofio | D11: p37 | E11: gr | F11: 0.02 | G11: simple | J11: Si
A12: Embutidos | B12: 14 | C12: Queso pimenton | D12: b04 | E12: gr | F12: 0.02 | G12: simple | J12: Si
A13: Embutidos | B13: 15 | C13: Queso fresco | D13: p38 | E13: gr | F13: 0.02 | G13: simple | J13: Si
A14: Estandar | B14: 26 | C14: Estándar buffet desayuno diario | E14: porciones | F14: 1 | G14: receta_estandar | I14: r137 | J14: Si
A15: Frutas | B15: 1 | C15: Kiwi | D15: p71 | E15: gr | F15: 0.08 | G15: simple | J15: Si
A16: Frutas | B16: 2 | C16: Papaya | D16: p70 | E16: gr | F16: 0.08 | G16: simple | J16: Si
A17: Frutas | B17: 3 | C17: Melon | D17: p69 | E17: gr | F17: 0.08 | G17: simple | J17: Si
A18: Frutas | B18: 4 | C18: Sandia | D18: p83 | E18: gr | F18: 0.08 | G18: simple | J18: Si
A19: Frutas | B19: 5 | C19: Pomelo | D19: p99 | E19: gr | F19: 0.08 | G19: simple | J19: Si
A20: Frutas | B20: 6 | C20: Naranja | D20: b06 | E20: gr | F20: 0.08 | G20: simple | J20: Si
A21: Frutas | B21: 7 | C21: Platano | D21: p66 | E21: Ud | F21: 1 | G21: simple | J21: Si
A22: Frutas | B22: 8 | C22: Pina | D22: p68 | E22: gr | F22: 0.08 | G22: simple | J22: Si
A23: Frutas | B23: 9 | C23: Melocoton almibar | D23: p122 | E23: Ud | F23: 1 | G23: simple | J23: Si
A24: Jarras | B24: 27 | C24: Jarra leche entera 1L | D24: p127 | E24: Ud | F24: 1 | G24: simple | J24: Si
A25: Jarras | B25: 28 | C25: Jarra leche semi 1L | D25: p128 | E25: Ud | F25: 1 | G25: simple | J25: Si
A26: Jarras | B26: 29 | C26: Jarra zumo manzana | E26: Ud | F26: 1 | G26: simple | J26: Si
A27: Jarras | B27: 30 | C27: Jarra zumo piña | E27: Ud | F27: 1 | G27: simple | J27: Si
A28: Jarras | B28: 31 | C28: Jarra zumo cranberry | E28: Ud | F28: 1 | G28: simple | J28: Si
A29: Jarras | B29: 32 | C29: Jarra zumo naranja | D29: b06 | E29: Ud | F29: 1 | G29: jarra_zumo | H29: b28 | J29: Si
A30: Pan | B30: 16 | C30: Pan gallego | D30: p05 | E30: ud | F30: 0.05 | G30: simple | J30: Si
A31: Pan | B31: 17 | C31: Pan maiz | D31: p357 | E31: ud | F31: 0.1 | G31: simple | J31: Si
A32: Pan | B32: 18 | C32: Pan centeno | D32: p276 | E32: ud | F32: 0.05 | G32: simple | J32: Si
A33: Pan | B33: 19 | C33: Baguettina | D33: p252 | E33: ud | F33: 0.015152 | G33: simple | J33: Si
A34: Porciones | B34: 33 | C34: Mantequilla porcion | D34: p152 | E34: gr | F34: 0.015 | G34: simple | J34: Si
A35: Porciones | B35: 34 | C35: Margarina porcion | D35: p153 | E35: gr | F35: 0.015 | G35: simple | J35: Si
A36: Porciones | B36: 35 | C36: Mermelada fresa | D36: p160 | E36: gr | F36: 0.02 | G36: simple | J36: Si
A37: Porciones | B37: 36 | C37: Mermelada naranja | D37: p161 | E37: gr | F37: 0.02 | G37: simple | J37: Si
A38: Porciones | B38: 37 | C38: Mermelada melocoton | D38: p162 | E38: gr | F38: 0.02 | G38: simple | J38: Si
A39: Porciones | B39: 38 | C39: Pate porcion | D39: p164 | E39: gr | F39: 0.02 | G39: simple | J39: Si
A40: Porciones | B40: 39 | C40: Sobrasada porcion | D40: p165 | E40: gr | F40: 0.02 | G40: simple | J40: Si
...

Sheet ConsumoBuffet
A1: Fecha | B1: Seccion | C1: Concepto | D1: Cantidad | E1: Motivo | F1: Naranjas | G1: ZumoBote | H1: Coste | I1: Notas | J1: Importado
H2: =IF(E2="Consumo",IFERROR(D2*VLOOKUP(VLOOKUP(C2,ConfigBuffet!$C:$D,2,FALSE),Precios!$A:$C,3,FALSE)*VLOOKUP(C2,ConfigBuffet!$C:$F,4,FALSE),0)+IFERROR(F2*VLOOKUP("b06",Precios!$A:$C,3,FALSE),0)+IFERROR(G2*VLOOKUP("b28",Precios!$A:$C,3,FALSE),0),0)
H3: =IF(E3="Consumo",IFERROR(D3*VLOOKUP(VLOOKUP(C3,ConfigBuffet!$C:$D,2,FALSE),Precios!$A:$C,3,FALSE)*VLOOKUP(C3,ConfigBuffet!$C:$F,4,FALSE),0)+IFERROR(F3*VLOOKUP("b06",Precios!$A:$C,3,FALSE),0)+IFERROR(G3*VLOOKUP("b28",Precios!$A:$C,3,FALSE),0),0)
H4: =IF(E4="Consumo",IFERROR(D4*VLOOKUP(VLOOKUP(C4,ConfigBuffet!$C:$D,2,FALSE),Precios!$A:$C,3,FALSE)*VLOOKUP(C4,ConfigBuffet!$C:$F,4,FALSE),0)+IFERROR(F4*VLOOKUP("b06",Precios!$A:$C,3,FALSE),0)+IFERROR(G4*VLOOKUP("b28",Precios!$A:$C,3,FALSE),0),0)
H5: =IF(E5="Consumo",IFERROR(D5*VLOOKUP(VLOOKUP(C5,ConfigBuffet!$C:$D,2,FALSE),Precios!$A:$C,3,FALSE)*VLOOKUP(C5,ConfigBuffet!$C:$F,4,FALSE),0)+IFERROR(F5*VLOOKUP("b06",Precios!$A:$C,3,FALSE),0)+IFERROR(G5*VLOOKUP("b28",Precios!$A:$C,3,FALSE),0),0)
H6: =IF(E6="Consumo",IFERROR(D6*VLOOKUP(VLOOKUP(C6,ConfigBuffet!$C:$D,2,FALSE),Precios!$A:$C,3,FALSE)*VLOOKUP(C6,ConfigBuffet!$C:$F,4,FALSE),0)+IFERROR(F6*VLOOKUP("b06",Precios!$A:$C,3,FALSE),0)+IFERROR(G6*VLOOKUP("b28",Precios!$A:$C,3,FALSE),0),0)
H7: =IF(E7="Consumo",IFERROR(D7*VLOOKUP(VLOOKUP(C7,ConfigBuffet!$C:$D,2,FALSE),Precios!$A:$C,3,FALSE)*VLOOKUP(C7,ConfigBuffet!$C:$F,4,FALSE),0)+IFERROR(F7*VLOOKUP("b06",Precios!$A:$C,3,FALSE),0)+IFERROR(G7*VLOOKUP("b28",Precios!$A:$C,3,FALSE),0),0)
H8: =IF(E8="Consumo",IFERROR(D8*VLOOKUP(VLOOKUP(C8,ConfigBuffet!$C:$D,2,FALSE),Precios!$A:$C,3,FALSE)*VLOOKUP(C8,ConfigBuffet!$C:$F,4,FALSE),0)+IFERROR(F8*VLOOKUP("b06",Precios!$A:$C,3,FALSE),0)+IFERROR(G8*VLOOKUP("b28",Precios!$A:$C,3,FALSE),0),0)
H9: =IF(E9="Consumo",IFERROR(D9*VLOOKUP(VLOOKUP(C9,ConfigBuffet!$C:$D,2,FALSE),Precios!$A:$C,3,FALSE)*VLOOKUP(C9,ConfigBuffet!$C:$F,4,FALSE),0)+IFERROR(F9*VLOOKUP("b06",Precios!$A:$C,3,FALSE),0)+IFERROR(G9*VLOOKUP("b28",Precios!$A:$C,3,FALSE),0),0)
H10: =IF(E10="Consumo",IFERROR(D10*VLOOKUP(VLOOKUP(C10,ConfigBuffet!$C:$D,2,FALSE),Precios!$A:$C,3,FALSE)*VLOOKUP(C10,ConfigBuffet!$C:$F,4,FALSE),0)+IFERROR(F10*VLOOKUP("b06",Precios!$A:$C,3,FALSE),0)+IFERROR(G10*VLOOKUP("b28",Precios!$A:$C,3,FALSE),0),0)
H11: =IF(E11="Consumo",IFERROR(D11*VLOOKUP(VLOOKUP(C11,ConfigBuffet!$C:$D,2,FALSE),Precios!$A:$C,3,FALSE)*VLOOKUP(C11,ConfigBuffet!$C:$F,4,FALSE),0)+IFERROR(F11*VLOOKUP("b06",Precios!$A:$C,3,FALSE),0)+IFERROR(G11*VLOOKUP("b28",Precios!$A:$C,3,FALSE),0),0)
H12: =IF(E12="Consumo",IFERROR(D12*VLOOKUP(VLOOKUP(C12,ConfigBuffet!$C:$D,2,FALSE),Precios!$A:$C,3,FALSE)*VLOOKUP(C12,ConfigBuffet!$C:$F,4,FALSE),0)+IFERROR(F12*VLOOKUP("b06",Precios!$A:$C,3,FALSE),0)+IFERROR(G12*VLOOKUP("b28",Precios!$A:$C,3,FALSE),0),0)
H13: =IF(E13="Consumo",IFERROR(D13*VLOOKUP(VLOOKUP(C13,ConfigBuffet!$C:$D,2,FALSE),Precios!$A:$C,3,FALSE)*VLOOKUP(C13,ConfigBuffet!$C:$F,4,FALSE),0)+IFERROR(F13*VLOOKUP("b06",Precios!$A:$C,3,FALSE),0)+IFERROR(G13*VLOOKUP("b28",Precios!$A:$C,3,FALSE),0),0)
... H149: =IF(E149="Consumo",IFERROR(D149*VLOOKUP(VLOOKUP(C149,ConfigBuffet!$C:$D,2,FALSE),Precios!$A:$C,3,FALSE)*VLOOKUP(C149,ConfigBuffet!$C:$F,4,FALSE),0)+IFERROR(F149*VLOOKUP("b06",Precios!$A:$C,3,FALSE),0)+IFERROR(G149*VLOOKUP("b28",Precios!$A:$C,3,FALSE),0),0)
G150: TOTAL | H150: =SUM(H2:H150)
H151: =IF(E151="Consumo",IFERROR(D151*VLOOKUP(VLOOKUP(C151,ConfigBuffet!$C:$D,2,FALSE),Precios!$A:$C,3,FALSE)*VLOOKUP(C151,ConfigBuffet!$C:$F,4,FALSE),0)+IFERROR(F151*VLOOKUP("b06",Precios!$A:$C,3,FALSE),0)+IFERROR(G151*VLOOKUP("b28",Precios!$A:$C,3,FALSE),0),0)
H152: =IF(E152="Consumo",IFERROR(D152*VLOOKUP(VLOOKUP(C152,ConfigBuffet!$C:$D,2,FALSE),Precios!$A:$C,3,FALSE)*VLOOKUP(C152,ConfigBuffet!$C:$F,4,FALSE),0)+IFERROR(F152*VLOOKUP("b06",Precios!$A:$C,3,FALSE),0)+IFERROR(G152*VLOOKUP("b28",Precios!$A:$C,3,FALSE),0),0)
H153: =IF(E153="Consumo",IFERROR(D153*VLOOKUP(VLOOKUP(C153,ConfigBuffet!$C:$D,2,FALSE),Precios!$A:$C,3,FALSE)*VLOOKUP(C153,ConfigBuffet!$C:$F,4,FALSE),0)+IFERROR(F153*VLOOKUP("b06",Precios!$A:$C,3,FALSE),0)+IFERROR(G153*VLOOKUP("b28",Precios!$A:$C,3,FALSE),0),0)
H154: =IF(E154="Consumo",IFERROR(D154*VLOOKUP(VLOOKUP(C154,ConfigBuffet!$C:$D,2,FALSE),Precios!$A:$C,3,FALSE)*VLOOKUP(C154,ConfigBuffet!$C:$F,4,FALSE),0)+IFERROR(F154*VLOOKUP("b06",Precios!$A:$C,3,FALSE),0)+IFERROR(G154*VLOOKUP("b28",Precios!$A:$C,3,FALSE),0),0)
H155: =IF(E155="Consumo",IFERROR(D155*VLOOKUP(VLOOKUP(C155,ConfigBuffet!$C:$D,2,FALSE),Precios!$A:$C,3,FALSE)*VLOOKUP(C155,ConfigBuffet!$C:$F,4,FALSE),0)+IFERROR(F155*VLOOKUP("b06",Precios!$A:$C,3,FALSE),0)+IFERROR(G155*VLOOKUP("b28",Precios!$A:$C,3,FALSE),0),0)
H156: =IF(E156="Consumo",IFERROR(D156*VLOOKUP(VLOOKUP(C156,ConfigBuffet!$C:$D,2,FALSE),Precios!$A:$C,3,FALSE)*VLOOKUP(C156,ConfigBuffet!$C:$F,4,FALSE),0)+IFERROR(F156*VLOOKUP("b06",Precios!$A:$C,3,FALSE),0)+IFERROR(G156*VLOOKUP("b28",Precios!$A:$C,3,FALSE),0),0)
H157: =IF(E157="Consumo",IFERROR(D157*VLOOKUP(VLOOKUP(C157,ConfigBuffet!$C:$D,2,FALSE),Precios!$A:$C,3,FALSE)*VLOOKUP(C157,ConfigBuffet!$C:$F,4,FALSE),0)+IFERROR(F157*VLOOKUP("b06",Precios!$A:$C,3,FALSE),0)+IFERROR(G157*VLOOKUP("b28",Precios!$A:$C,3,FALSE),0),0)
H158: =IF(E158="Consumo",IFERROR(D158*VLOOKUP(VLOOKUP(C158,ConfigBuffet!$C:$D,2,FALSE),Precios!$A:$C,3,FALSE)*VLOOKUP(C158,ConfigBuffet!$C:$F,4,FALSE),0)+IFERROR(F158*VLOOKUP("b06",Precios!$A:$C,3,FALSE),0)+IFERROR(G158*VLOOKUP("b28",Precios!$A:$C,3,FALSE),0),0)
H159: =IF(E159="Consumo",IFERROR(D159*VLOOKUP(VLOOKUP(C159,ConfigBuffet!$C:$D,2,FALSE),Precios!$A:$C,3,FALSE)*VLOOKUP(C159,ConfigBuffet!$C:$F,4,FALSE),0)+IFERROR(F159*VLOOKUP("b06",Precios!$A:$C,3,FALSE),0)+IFERROR(G159*VLOOKUP("b28",Precios!$A:$C,3,FALSE),0),0)
H160: =IF(E160="Consumo",IFERROR(D160*VLOOKUP(VLOOKUP(C160,ConfigBuffet!$C:$D,2,FALSE),Precios!$A:$C,3,FALSE)*VLOOKUP(C160,ConfigBuffet!$C:$F,4,FALSE),0)+IFERROR(F160*VLOOKUP("b06",Precios!$A:$C,3,FALSE),0)+IFERROR(G160*VLOOKUP("b28",Precios!$A:$C,3,FALSE),0),0)
H161: =IF(E161="Consumo",IFERROR(D161*VLOOKUP(VLOOKUP(C161,ConfigBuffet!$C:$D,2,FALSE),Precios!$A:$C,3,FALSE)*VLOOKUP(C161,ConfigBuffet!$C:$F,4,FALSE),0)+IFERROR(F161*VLOOKUP("b06",Precios!$A:$C,3,FALSE),0)+IFERROR(G161*VLOOKUP("b28",Precios!$A:$C,3,FALSE),0),0)
H162: =IF(E162="Consumo",IFERROR(D162*VLOOKUP(VLOOKUP(C162,ConfigBuffet!$C:$D,2,FALSE),Precios!$A:$C,3,FALSE)*VLOOKUP(C162,ConfigBuffet!$C:$F,4,FALSE),0)+IFERROR(F162*VLOOKUP("b06",Precios!$A:$C,3,FALSE),0)+IFERROR(G162*VLOOKUP("b28",Precios!$A:$C,3,FALSE),0),0)
... H230: =IF(E230="Consumo",IFERROR(D230*VLOOKUP(VLOOKUP(C230,ConfigBuffet!$C:$D,2,FALSE),Precios!$A:$C,3,FALSE)*VLOOKUP(C230,ConfigBuffet!$C:$F,4,FALSE),0)+IFERROR(F230*VLOOKUP("b06",Precios!$A:$C,3,FALSE),0)+IFERROR(G230*VLOOKUP("b28",Precios!$A:$C,3,FALSE),0),0)
G231: TOTAL | H231: =SUM(H2:H231)
H232: =IF(E232="Consumo",IFERROR(D232*VLOOKUP(VLOOKUP(C232,ConfigBuffet!$C:$D,2,FALSE),Precios!$A:$C,3,FALSE)*VLOOKUP(C232,ConfigBuffet!$C:$F,4,FALSE),0)+IFERROR(F232*VLOOKUP("b06",Precios!$A:$C,3,FALSE),0)+IFERROR(G232*VLOOKUP("b28",Precios!$A:$C,3,FALSE),0),0)
H233: =IF(E233="Consumo",IFERROR(D233*VLOOKUP(VLOOKUP(C233,ConfigBuffet!$C:$D,2,FALSE),Precios!$A:$C,3,FALSE)*VLOOKUP(C233,ConfigBuffet!$C:$F,4,FALSE),0)+IFERROR(F233*VLOOKUP("b06",Precios!$A:$C,3,FALSE),0)+IFERROR(G233*VLOOKUP("b28",Precios!$A:$C,3,FALSE),0),0)
H234: =IF(E234="Consumo",IFERROR(D234*VLOOKUP(VLOOKUP(C234,ConfigBuffet!$C:$D,2,FALSE),Precios!$A:$C,3,FALSE)*VLOOKUP(C234,ConfigBuffet!$C:$F,4,FALSE),0)+IFERROR(F234*VLOOKUP("b06",Precios!$A:$C,3,FALSE),0)+IFERROR(G234*VLOOKUP("b28",Precios!$A:$C,3,FALSE),0),0)
H235: =IF(E235="Consumo",IFERROR(D235*VLOOKUP(VLOOKUP(C235,ConfigBuffet!$C:$D,2,FALSE),Precios!$A:$C,3,FALSE)*VLOOKUP(C235,ConfigBuffet!$C:$F,4,FALSE),0)+IFERROR(F235*VLOOKUP("b06",Precios!$A:$C,3,FALSE),0)+IFERROR(G235*VLOOKUP("b28",Precios!$A:$C,3,FALSE),0),0)
H236: =IF(E236="Consumo",IFERROR(D236*VLOOKUP(VLOOKUP(C236,ConfigBuffet!$C:$D,2,FALSE),Precios!$A:$C,3,FALSE)*VLOOKUP(C236,ConfigBuffet!$C:$F,4,FALSE),0)+IFERROR(F236*VLOOKUP("b06",Precios!$A:$C,3,FALSE),0)+IFERROR(G236*VLOOKUP("b28",Precios!$A:$C,3,FALSE),0),0)
H237: =IF(E237="Consumo",IFERROR(D237*VLOOKUP(VLOOKUP(C237,ConfigBuffet!$C:$D,2,FALSE),Precios!$A:$C,3,FALSE)*VLOOKUP(C237,ConfigBuffet!$C:$F,4,FALSE),0)+IFERROR(F237*VLOOKUP("b06",Precios!$A:$C,3,FALSE),0)+IFERROR(G237*VLOOKUP("b28",Precios!$A:$C,3,FALSE),0),0)
H238: =IF(E238="Consumo",IFERROR(D238*VLOOKUP(VLOOKUP(C238,ConfigBuffet!$C:$D,2,FALSE),Precios!$A:$C,3,FALSE)*VLOOKUP(C238,ConfigBuffet!$C:$F,4,FALSE),0)+IFERROR(F238*VLOOKUP("b06",Precios!$A:$C,3,FALSE),0)+IFERROR(G238*VLOOKUP("b28",Precios!$A:$C,3,FALSE),0),0)
H239: =IF(E239="Consumo",IFERROR(D239*VLOOKUP(VLOOKUP(C239,ConfigBuffet!$C:$D,2,FALSE),Precios!$A:$C,3,FALSE)*VLOOKUP(C239,ConfigBuffet!$C:$F,4,FALSE),0)+IFERROR(F239*VLOOKUP("b06",Precios!$A:$C,3,FALSE),0)+IFERROR(G239*VLOOKUP("b28",Precios!$A:$C,3,FALSE),0),0)
H240: =IF(E240="Consumo",IFERROR(D240*VLOOKUP(VLOOKUP(C240,ConfigBuffet!$C:$D,2,FALSE),Precios!$A:$C,3,FALSE)*VLOOKUP(C240,ConfigBuffet!$C:$F,4,FALSE),0)+IFERROR(F240*VLOOKUP("b06",Precios!$A:$C,3,FALSE),0)+IFERROR(G240*VLOOKUP("b28",Precios!$A:$C,3,FALSE),0),0)
H241: =IF(E241="Consumo",IFERROR(D241*VLOOKUP(VLOOKUP(C241,ConfigBuffet!$C:$D,2,FALSE),Precios!$A:$C,3,FALSE)*VLOOKUP(C241,ConfigBuffet!$C:$F,4,FALSE),0)+IFERROR(F241*VLOOKUP("b06",Precios!$A:$C,3,FALSE),0)+IFERROR(G241*VLOOKUP("b28",Precios!$A:$C,3,FALSE),0),0)
H242: =IF(E242="Consumo",IFERROR(D242*VLOOKUP(VLOOKUP(C242,ConfigBuffet!$C:$D,2,FALSE),Precios!$A:$C,3,FALSE)*VLOOKUP(C242,ConfigBuffet!$C:$F,4,FALSE),0)+IFERROR(F242*VLOOKUP("b06",Precios!$A:$C,3,FALSE),0)+IFERROR(G242*VLOOKUP("b28",Precios!$A:$C,3,FALSE),0),0)
...

Sheet RegistroComida
A1: Fecha | B1: Tipo | C1: Nombre | D1: Cantidad ↑↓ | E1: Notas | F1: Importado

Sheet RegistroCena
A1: Fecha | B1: Tipo | C1: Nombre | D1: Cantidad ↑↓ | E1: Notas | F1: Importado

Sheet RegistroBebidasDesayuno
A1: Fecha | B1: Tipo | C1: Nombre | D1: Cantidad ↑↓ | E1: Notas | F1: Importado
